# 예외 처리

## 코루틴의 예외 전파 

코루틴 실행 도중 예외가 발생하면 예외가 발생한 코루틴은 취소되고 부모 코루틴으로 예외가 전파된다. 
만약 부모 코루틴에서도 예외가 적절히 처리되지 않으면 부모 코루틴도 취소되고 예외는 다시 상위 코루틴으로 전파되는데 이것이 반복되면 최상위 코루틴인 루트 코루틴까지 예외가 전파될 수 있다.

코루틴이 예외를 전파받아 취소되면 해당 코루틴만 취소되는 것이 아니라 코루틴의 특성에 따라 해당 코루틴의 하위에 있는 모든 코루틴에게 취소가 전파된다.

```text
Coroutine1 
- Coroutine2
    - Coroutine4
- Coroutine3
    - Coroutine5
    - Coroutine6
```

위와 같은 상황에서 Coroutine4에 예외가 발생했다면 Coroutine2로 예외가 전파되고 Coroutine2에서 적절한 예외처리를 하지 않았다면 Coroutine1로 예외가 전파된다.
이어서 Coroutine1은 Coroutine3으로 취소를 전파하고 Coroutine3은 Coroutine5, Coroutine6에 취소를 전파한다.

```kotlin
fun main() = runBlocking {
    launch(CoroutineName("Coroutine1")) {
        launch(CoroutineName("Coroutine3")) {
            throw Exception("예외 발생!")
        }
        delay(100L)
        println("[${Thread.currentThread().name}] 코루틴 실행")
    }
    launch(CoroutineName("Coroutine2")) {
        delay(100L)
        println("[${Thread.currentThread().name}] 코루틴 실행")
    }
    delay(1000L)
}
```

```text
Exception in thread "main" java.lang.Exception: 예외 발생!
	at standardcoroutine.ExceptionHandlingKt$main$1$1$1.invokeSuspend(ExceptionHandling.kt:11)
	at kotlin.coroutines.jvm.internal.BaseContinuationImpl.resumeWith(ContinuationImpl.kt:33)
	at kotlinx.coroutines.DispatchedTask.run(DispatchedTask.kt:108)
	at kotlinx.coroutines.EventLoopImplBase.processNextEvent(EventLoop.common.kt:280)
	at kotlinx.coroutines.BlockingCoroutine.joinBlocking(Builders.kt:85)
	at kotlinx.coroutines.BuildersKt__BuildersKt.runBlocking(Builders.kt:59)
	at kotlinx.coroutines.BuildersKt.runBlocking(Unknown Source)
	at kotlinx.coroutines.BuildersKt__BuildersKt.runBlocking$default(Builders.kt:38)
	at kotlinx.coroutines.BuildersKt.runBlocking$default(Unknown Source)
	at standardcoroutine.ExceptionHandlingKt.main(ExceptionHandling.kt:8)
	at standardcoroutine.ExceptionHandlingKt.main(ExceptionHandling.kt)
```

위 예제를 풀어보면 코루틴3에서 발생한 예외가 코루틴1로 전파되고 코루틴1에서 별다른 예외 처리 로직이 없기때문에 runBlocking 코루틴으로 전파된다.
이어서 runBlocking 코루틴은 코루틴2에 취소를 전파하여 코루틴2는 취소된다.

## 예외 전파 제한

### Job 객체를 사용해 예외 전파 제한하기

코루틴의 예외 전파를 제한하기 위한 첫 번째 방법은 코루틴의 구조화를 깨는 것이다. (코루틴은 자신의 부모 코루틴으로만 예외를 전파하는 특성을 가지기 때문)

```kotlin
suspend fun blockingExceptionPropagationUsingJobTest(coroutineScope: CoroutineScope) {
    coroutineScope.launch(CoroutineName("Parent Job")) {
        launch(CoroutineName("Coroutine1") + Job()) {// 새로운 Job 생성 -> 루트 코루틴 
            launch(CoroutineName("Coroutine3")) {
                throw Exception("예외 발생!")
            }
            delay(100L)
            println("[${Thread.currentThread().name}] 코루틴 실행")
        }
        launch(CoroutineName("Coroutine2")) {
            delay(100L)
            println("[${Thread.currentThread().name}] 코루틴 실행")
        }
    }
    delay(1000L)
}
```

Job()을 통해 새로운 루트 코루틴을 설정하여 기존 구조화를 깰 수 있다.
코루틴3에서 발생한 예외는 코루틴1로만 전파가 되고 코루틴1은 루트 코루틴이므로 더 이상 전파되지 않는다. 따라서 코루틴2는 정상 출력된다.

하지만 이러한 방식은 예외 전파를 제한하는 것뿐만 아니라 취소 전파도 제한시킨다. 
일반적으로 코루틴의 구조화는 큰 작업을 연관된 작은 작업으로 나누는 과정을 통해 일어난다. 만약 작은 작업의 구조화가 깨진다면 큰 작업에 취소가 요청되더라도 작은 작업은 취소되지 않으며 이는 비동기 작업을 불안정하게 만든다.

```kotlin
suspend fun limitBlockingExceptionPropagationUsingJobTest(coroutineScope: CoroutineScope) {
    val parentJob = coroutineScope.launch(CoroutineName("Parent Job")) {
        launch(CoroutineName("Coroutine1") + Job()) {// 새로운 Job 생성 -> 루트 코루틴
            launch(CoroutineName("Coroutine3")) {
                delay(100L)
                println("[${Thread.currentThread().name}] 코루틴 실행")
            }
            delay(100L)
            println("[${Thread.currentThread().name}] 코루틴 실행")
        }
        launch(CoroutineName("Coroutine2")) {
            delay(100L)
            println("[${Thread.currentThread().name}] 코루틴 실행")
        }
    }
    delay(20L)
    parentJob.cancel()
    delay(1000L)
}
```

```text
[main @Coroutine1#3] 코루틴 실행
[main @Coroutine3#5] 코루틴 실행
```

코루틴1은 더 이상 Parent 코루틴의 자식 코루틴이 아니기 때문에 취소가 전파되지 않는다.
안정적으로 동작하기 위해서는 Parent 코루틴이 취소되면 코루틴1과 코루틴3도 함께 취소돼야 한다.

**구조화를 깨지 않으면서 예외 전파를 제한하는 방법은 없을까?**

### SupervisorJob 객체를 사용한 예외 전파 제한

코루틴 라이브러리는 구조화를 깨지 않으면서 예외 전파를 제한할 수 있도록 SupervisorJob 객체를 제공한다.

SupervisorJob 객체는 자식 코루틴으로부터 예외를 전파받지 않는 특수한 Job 객체로 하나의 자식 코루틴에서 발생한 예외가 다른 자식 코루틴에게 영향을 미치지 못하도록 만드는 데 사용한다.

> SupervisorJob은 자식 코루틴으로 취소를 전파하지 않는것이 아닌 자식 코루틴으로부터 예외를 전파받지 않는 것이다. 단, 예외에 대한 정보는 받는다.

```kotlin
@Suppress("FunctionName")
public fun SupervisorJob(parent: Job? = null) : CompletableJob = SupervisorJobImpl(parent)
```

기존 Job()과 동일하게 parent 파라미터를 전달하지 않으면 루트 코루틴이 된다.


```kotlin
suspend fun blockingExceptionPropagationUsingSupervisorJobTest(coroutineScope: CoroutineScope) {
    val supervisorJob = SupervisorJob()
    coroutineScope.launch(CoroutineName("Coroutine1") + supervisorJob) {
        launch(CoroutineName("Coroutine3")) {
            throw Exception("예외 발생!")
        }
        delay(100L)
        println("[${Thread.currentThread().name}] 코루틴 실행")
    }
    coroutineScope.launch(CoroutineName("Coroutine2") + supervisorJob) {
        delay(100L)
        println("[${Thread.currentThread().name}] 코루틴 실행")
    }
    delay(1000L)
}
```

```text
Exception in thread "main @Coroutine1 Job#2" java.lang.Exception: 예외 발생!
	at standardcoroutine.ExceptionHandlingKt$blockingExceptionPropagationUsingSupervisorJobTest$2$1.invokeSuspend(ExceptionHandling.kt:16)
	at kotlin.coroutines.jvm.internal.BaseContinuationImpl.resumeWith(ContinuationImpl.kt:33)
	at kotlinx.coroutines.DispatchedTask.run(DispatchedTask.kt:108)
	at kotlinx.coroutines.EventLoopImplBase.processNextEvent(EventLoop.common.kt:280)
	at kotlinx.coroutines.BlockingCoroutine.joinBlocking(Builders.kt:85)
	at kotlinx.coroutines.BuildersKt__BuildersKt.runBlocking(Builders.kt:59)
	at kotlinx.coroutines.BuildersKt.runBlocking(Unknown Source)
	at kotlinx.coroutines.BuildersKt__BuildersKt.runBlocking$default(Builders.kt:38)
	at kotlinx.coroutines.BuildersKt.runBlocking$default(Unknown Source)
	at standardcoroutine.ExceptionHandlingKt.main(ExceptionHandling.kt:5)
	at standardcoroutine.ExceptionHandlingKt.main(ExceptionHandling.kt)
	Suppressed: kotlinx.coroutines.internal.DiagnosticCoroutineContextException: [CoroutineName(Coroutine1 Job), CoroutineId(2), "Coroutine1 Job#2":StandaloneCoroutine{Cancelling}@971d0d8, BlockingEventLoop@51931956]
[main @Coroutine2#3] 코루틴 실행
```

코루틴3에서 발생한 예외는 코루틴1로 전파되어 취소시키지만 코루틴1은 supervisorJob으로 예외를 전파하지 않는다.

하지만 여전히 이 코드에는 문제가 존재한다, SupervisorJob 객체가 runBlocking이 호출돼 만들어진 Job 객체와의 구조화를 깬다는 점이다.

### 코루틴의 구조화를 깨지 않고 SupervisorJob 사용하기

```kotlin
suspend fun blockingExceptionPropagationUsingSupervisorJobTest2(coroutineScope: CoroutineScope) {
    val supervisorJob = SupervisorJob(coroutineScope.coroutineContext.job)
    coroutineScope.launch(CoroutineName("Coroutine1 Job") + supervisorJob) {
        launch(CoroutineName("Coroutine3")) {
            throw Exception("예외 발생!")
        }
        delay(100L)
        println("[${Thread.currentThread().name}] 코루틴 실행")
    }
    coroutineScope.launch(CoroutineName("Coroutine2") + supervisorJob) {
        delay(100L)
        println("[${Thread.currentThread().name}] 코루틴 실행")
    }
    supervisorJob.complete()
}
```

구조화를 깨지 않고 SupervisorJob을 사용하기 위해서는 SupervisorJob Parent 파라미터로 부모 Job 객체를 넘기면 된다.
하지만 이러한 구조에서는 앞서 살펴봤다싶이 자동으로 완료 상태로 만들지 않기 때문에 `supervisorJob.complete()` 호출하여 상태를 실행 완료 상태로 변경해야 프로세스가 정상 종료된다.

### SupervisorJob을 CoroutineScope와 함께 사용하기

만약 CoroutineScope의 CoroutineContext에 SupervisorJob 객체가 설정된다면 CoroutineScope의 자식 코루틴에서 발생하는 예외가 다른 자식 코루틴으로 전파되지 않는다.

```kotlin
suspend fun blockingExceptionPropagationUsingSupervisorJobWithCoroutineScopeTest() {
    val coroutineScope = CoroutineScope(SupervisorJob())
    coroutineScope.launch(CoroutineName("Coroutine1")) {
        launch(CoroutineName("Coroutine3")) {
            throw Exception("예외 발생!")
        }
        delay(100L)
        println("[${Thread.currentThread().name}] 코루틴 실행")
    }

    coroutineScope.launch(CoroutineName("Coroutine2")) {
        delay(100L)
        println("[${Thread.currentThread().name}] 코루틴 실행")
    }
    delay(1000L)
}
```

```text
Exception in thread "DefaultDispatcher-worker-1 @Coroutine1#2" java.lang.Exception: 예외 발생!
	at standardcoroutine.ExceptionHandlingKt$blockingExceptionPropagationUsingSupervisorJobWithCoroutineScopeTest$2$1.invokeSuspend(ExceptionHandling.kt:18)
	at kotlin.coroutines.jvm.internal.BaseContinuationImpl.resumeWith(ContinuationImpl.kt:33)
	at kotlinx.coroutines.DispatchedTask.run(DispatchedTask.kt:108)
	at kotlinx.coroutines.scheduling.CoroutineScheduler.runSafely(CoroutineScheduler.kt:584)
	at kotlinx.coroutines.scheduling.CoroutineScheduler$Worker.executeTask(CoroutineScheduler.kt:793)
	at kotlinx.coroutines.scheduling.CoroutineScheduler$Worker.runWorker(CoroutineScheduler.kt:697)
	at kotlinx.coroutines.scheduling.CoroutineScheduler$Worker.run(CoroutineScheduler.kt:684)
	Suppressed: kotlinx.coroutines.internal.DiagnosticCoroutineContextException: [CoroutineName(Coroutine1), CoroutineId(2), "Coroutine1#2":StandaloneCoroutine{Cancelling}@28fb8b6e, Dispatchers.Default]
[DefaultDispatcher-worker-1 @Coroutine2#3] 코루틴 실행
```

### SupervisorJob을 사용할 때 흔히 하는 실수

SupervisorJob 사용 시 흔히 하는 실수는 예외 전파 방지를 위해 코루틴 빌더 함수의 context 인자에 SupervisorJob()을 넘기고, 코루틴 빌더 함수가 호출돼 생성되는 코루틴의 하위 자식 코루틴들을 생성하는 것이다.

```kotlin
suspend fun mistakeSupervisorJobTest(coroutineScope: CoroutineScope) {
    coroutineScope.launch(CoroutineName("Parent Coroutine") + SupervisorJob()) {
        launch(CoroutineName("Coroutine1")) {
            launch(CoroutineName("Coroutine3")) {
                throw Exception("예외 발생!")
            }
            delay(100L)
            println("[${Thread.currentThread().name}] 코루틴 실행")
        }
        launch(CoroutineName("Coroutine2")) {
            delay(100L)
            println("[${Thread.currentThread().name}] 코루틴 실행")
        }
    }
    delay(1000L)
}
```

위 코드는 문제가 없어보이고 실행 시 코루틴3에서 발생한 예외가 코루틴2의 실행을 취소하지 않는걸 기대할 수 있지만 위 코드를 실행하면 코루틴2는 실행되지 않는다.
그 이유는 launch 함수의 context로 Job이 주어지면 주어진 Job을 부모로 하는 새로운 Job을 생성하기 때문이다.

```text
SupervisorJob
- Parent Coroutine Job
    - Coroutine1 Job
        - Coroutine3 Job
    - Coroutine2 Job
```

- Coroutine3 예외 발생 -> 코루틴 1 예외 전파 -> Parent 코루틴 예외 전파 (SupervisorJob X) -> Parent 코루틴은 코루틴2로 취소 전파 

### supervisorScope를 사용한 예외 전파 제한

SupervisorJob() 대안으로 supervisorScope 함수를 사용할 수 있다.
SupervisorJob 객체를 가진 CoroutineScope 객체를 생성하며, 이 SupervisorJob 객체는 supervisorScope 함수를 호출한 코루틴의 Job 객체를 부모로 가진다.

supervisorScope 내부에서 실행되는 코루틴은 SupervisorJob과 부모-자식 관계로 구조화되는데 supervisorScope의 SupervisorJob 객체는 코드가 모두 실행되고 자식 코루틴도 모두 실행 완료되면 자동으로 완료 처리된다. 

```kotlin
suspend fun blockingExceptionPropagationUsingSupervisorScopeTest() {
    supervisorScope {
        launch(CoroutineName("Coroutine1")) {
            launch(CoroutineName("Coroutine3")) {
                throw Exception("예외 발생!")
            }
            delay(100L)
            println("[${Thread.currentThread().name}] 코루틴 실행")
        }
        launch(CoroutineName("Coroutine2")) {
            delay(100L)
            println("[${Thread.currentThread().name}] 코루틴 실행")
        }
    }
}
```

위 코드는 runBlocking 함수에 의해 Job 객체가 생성되고, Job 객체는 자식 코루틴으로 coroutineScope 함수에 의해 생성된 SupervisorJob 객체를 가진다.

```text
runBlockingJob
- SupervisorJob
    - Coroutine1 Job
        - Coroutine3 Job
    - Coroutine2 Job
```

## CoroutineExceptionHandler를 사용한 에외 처리

구조화된 코루틴들에 공통적인 예외 처리기를 설정해야 할 경우도 있다. 코루틴은 이를 위해 CoroutineContext 구성 요소로 CoroutineExceptionHandler라고 하는 예외 처리기를 지원한다.

```kotlin
@Suppress("FunctionName")
public inline fun CoroutineExceptionHandler(crossinline handler: (CoroutineContext, Throwable) -> Unit): CoroutineExceptionHandler =
    object : AbstractCoroutineContextElement(CoroutineExceptionHandler), CoroutineExceptionHandler {
        override fun handleException(context: CoroutineContext, exception: Throwable) =
            handler.invoke(context, exception)
    }
```

CoroutineExceptionHandler는 CoroutineExceptionHandler 함수를 통해 생성할 수 있다.
CoroutineExceptionHandler 함수는 람다식인 handler를 매개변수로 가지는데, CoroutineContext와 Throwable 타입의 매개변수를 갖는 람다식으로 이 람다식에 예외가 발생했을 때 어떤 동작을 할지입력해 예외를 처리할 수 있다.

```kotlin
suspend fun coroutineExceptionHandlerTest() {
    val exceptionHandler = CoroutineExceptionHandler { coroutineContext, throwable ->
        println("[예외 발생] ${throwable}")
    }
    CoroutineScope(exceptionHandler).launch(CoroutineName("Coroutine1")) {
        throw Exception("Coroutine1 예외 발생!!")
    }
    delay(1000)
}
```

```text
[예외 발생] java.lang.Exception: Coroutine1 예외 발생!!
```

CoroutineScope 함수가 호출되면 기본적으로 Job 객체가 새로 생성되므로 runBlocking이 호출돼 생성되는 Job 객체와의 구조화가 깨지며, Coroutine1은 CoroutineScope로부터 CoroutineContext를 제공받아 exceptionHandler가 상속된다.
즉, CoroutineScope에 의해 생성된 코루틴에도 exceptionHandler를 가지며, Coroutine1에도 exceptionHandler를 가진 상태가 된다.

**그렇다면 둘 중 어디에 설정된 exceptionHandler가 예외를 처리한 것일까?**

### 처리되지 않은 예외만 처리하는 CoroutineExceptionHandler

CoroutineExceptionHandler는 처리되지 안은 예외만 처리한다.
만약 자식 코루틴이 부모 코루틴으로 예외를 전파하면 자식 코루틴에서는 예외가 처리된 것으로 봐 자식 코루틴에 설정된 CoroutineExceptionHandler 객체는 동작하지 않는다. 

```kotlin
suspend fun coroutineExceptionHandlerTest2(coroutineScope: CoroutineScope) {
    val exceptionHandler = CoroutineExceptionHandler { coroutineContext, throwable ->
        println("[예외 발생] $throwable")
    }
    coroutineScope.launch(CoroutineName("Coroutine1") + exceptionHandler) {
        throw Exception("Coroutine1 예외 발생!!")
    }
    delay(1000)
}
```

```text
Exception in thread "main" java.lang.Exception: Coroutine1 예외 발생!!
	at standardcoroutine.ExceptionHandlingKt$coroutineExceptionHandlerTest2$2.invokeSuspend(ExceptionHandling.kt:23)
	at kotlin.coroutines.jvm.internal.BaseContinuationImpl.resumeWith(ContinuationImpl.kt:33)
	at kotlinx.coroutines.DispatchedTask.run(DispatchedTask.kt:108)
	at kotlinx.coroutines.EventLoopImplBase.processNextEvent(EventLoop.common.kt:280)
	at kotlinx.coroutines.BlockingCoroutine.joinBlocking(Builders.kt:85)
	at kotlinx.coroutines.BuildersKt__BuildersKt.runBlocking(Builders.kt:59)
	at kotlinx.coroutines.BuildersKt.runBlocking(Unknown Source)
	at kotlinx.coroutines.BuildersKt__BuildersKt.runBlocking$default(Builders.kt:38)
	at kotlinx.coroutines.BuildersKt.runBlocking$default(Unknown Source)
	at standardcoroutine.ExceptionHandlingKt.main(ExceptionHandling.kt:5)
	at standardcoroutine.ExceptionHandlingKt.main(ExceptionHandling.kt)
```

위 코드는 runBlocking 코루틴의 자식 코루틴으로 Coroutine1이 생성되고, exceptionHandler는 Coroutine1에만 설정된다.

코루틴1이 runBlocking 코루틴에 예외를 전파했기 때문에 오류 로그만 확인된다.
코루틴은 예외가 전파되면 예외를 처리한 것으로 보며, CoroutineExceptionHandler 객체는 이미 처리된 예외에 대해서는 동작하지 않는다.
구조화된 코루틴상에 여러 CoroutineExceptionHandler 객체가 설정돼 있더라도 마지막으로 예외를 전파받는 위치(예외가 처리되는 위치)에 설정된 CoroutineExceptionHandler 객체만 예외를 처리한다.
이런 특징 때문에 CoroutineExceptionHandler 객체는 '공통 예외 처리기'로써 동작할 수 있다.

따라서 CoroutineExceptionHandler 객체가 동작하도록 만들기 위해서는 CoroutineExceptionHandler 객체가 설정된 위치를 오류가 처리되는 위치로 만들어야 한다.
마지막으로 전파되는 위치에 CoroutineExceptionHandler 객체를 설정하면 예외 처리기가 동작하도록 만들 수 있다.

### Job과 CoroutineExceptionHandler 함께 설정하기

CoroutineExceptionHandler 객체가 예외를 처리하게 하는 가장 간단한 방법은 CoroutineExceptionHandler 객체를 루트 Job과 함께 설정하는 것이다.

```kotlin
suspend fun coroutineExceptionHandlerUsingJobTest(coroutineScope: CoroutineScope) {
    val exceptionHandler = CoroutineExceptionHandler { coroutineContext, throwable ->
        println("[예외 발생] $throwable")
    }
    val coroutineContext = Job() + exceptionHandler
    coroutineScope.launch(CoroutineName("Coroutine1") + coroutineContext) {
        throw Exception("Coroutine1 예외 발생!!")
    }
    delay(1000)
}
```

```text
[예외 발생] java.lang.Exception: Coroutine1 예외 발생!!
```

### SupervisorJob과 CoroutineExceptionHandler 함께 설정하기

SupervisorJob은 예외를 전파받지 않으므로 CoroutineExceptionHandler가 동작하지 않는다고 생각할 수 있지만 전파받지 않을뿐 예외에 대한 정보는 받기 때문에 CoroutineExceptionHandler 예외를 처리할 수 있다.

```kotlin
suspend fun coroutineExceptionHandlerUsingSupervisorJobTest(coroutineScope: CoroutineScope) {
    val exceptionHandler = CoroutineExceptionHandler { coroutineContext, throwable ->
        println("[예외 발생] $throwable")
    }
    val supervisedScope = CoroutineScope(SupervisorJob() + exceptionHandler)
    supervisedScope.apply {
        launch(CoroutineName("Coroutine1")) {
            throw Exception("Coroutine1 예외 발생!!")
        }
        launch(CoroutineName("Coroutine2")) {
            delay(100L)
            println("[${Thread.currentThread().name}] 코루틴 실행")
        }
    }
    delay(1000)
}
```

```text
[예외 발생] java.lang.Exception: Coroutine1 예외 발생!!
[DefaultDispatcher-worker-2 @Coroutine2#3] 코루틴 실행
```

### CoroutineExceptionHandler는 예외 전파를 제한하지 않는다.

CoroutineExceptionHandler 사용 시 많이 하는 실수는 CoroutineExceptionHandler가 try catch문처럼 동작해 예외 전파를 제한한다고 생각하는 것이다.
하지만 CoroutineExceptionHandler는 예외가 마지막으로 처리되는 위치에서 예외를 처리할 뿐, 예외 전파를 제한하지 않는다.

```kotlin
fun mistakeCoroutineExceptionHandlerTest(coroutineScope: CoroutineScope) {
    val exceptionHandler = CoroutineExceptionHandler { coroutineContext, throwable ->
        println("[예외 발생] $throwable")
    }
    coroutineScope.launch(CoroutineName("Coroutine1") + exceptionHandler) {
        throw Exception("Coroutine1 예외 발생!!")
    }
}
```

해당 코드는 프로세스가 비정상 종료된다. 
그 이유는 CoroutineExceptionHandler는 예외 전파를 제한하지 않기 때문이다. 

즉, 코루틴1에서 발생한 예외는 runBlocking 코루틴으로 전파되고, runBlocking 코루틴에는 CoroutineExceptionHandler이 설정되지 않았으므로 비정상 종료된다.

## try catch문을 사용한 예외 처리

```kotlin
fun exceptionHandlingUsingTryCatchTest(coroutineScope: CoroutineScope) {
    coroutineScope.launch(CoroutineName("Coroutine1")) {
        try {
            throw Exception("Coroutine1 예외 발생!!")
        } catch (e: Exception) {
            println(e.message)
        }
    }
    coroutineScope.launch(CoroutineName("Coroutine2")) {
        delay(1000)
        println("[${Thread.currentThread().name}] 코루틴 실행 완료")
    }
}
```

```text
Coroutine1 예외 발생!!
[main @Coroutine2#3] 코루틴 실행
```

## 코루틴 빌더 함수에 대한 try catch문은 코루틴의 예외를 잡지 못한다

try catch문 사용 시 많이 하는 실수는 try catch문을 코루틴 빌더 함수에 사용하는 것이다.
코루틴 빌더 함수에 try catch 문을 사용하면 코루틴에서 발생한 예외가 잡히지 않는다.

```kotlin
fun exceptionHandlingUsingTryCatchTest2(coroutineScope: CoroutineScope) {
    try {
        coroutineScope.launch(CoroutineName("Coroutine1")) {
            throw Exception("Coroutine1 예외 발생!!")
        }
    } catch (e: Exception) {
        println(e.message)
    }
    coroutineScope.launch(CoroutineName("Coroutine2")) {
        delay(1000)
        println("[${Thread.currentThread().name}] 코루틴 실행 완료")
    }
}
```

```text
Exception in thread "main" java.lang.Exception: Coroutine1 예외 발생!!
	at standardcoroutine.ExceptionHandlingKt$exceptionHandlingUsingTryCatchTest2$1.invokeSuspend(ExceptionHandling.kt:27)
	at kotlin.coroutines.jvm.internal.BaseContinuationImpl.resumeWith(ContinuationImpl.kt:33)
	at kotlinx.coroutines.DispatchedTask.run(DispatchedTask.kt:108)
	at kotlinx.coroutines.EventLoopImplBase.processNextEvent(EventLoop.common.kt:280)
	at kotlinx.coroutines.BlockingCoroutine.joinBlocking(Builders.kt:85)
	at kotlinx.coroutines.BuildersKt__BuildersKt.runBlocking(Builders.kt:59)
	at kotlinx.coroutines.BuildersKt.runBlocking(Unknown Source)
	at kotlinx.coroutines.BuildersKt__BuildersKt.runBlocking$default(Builders.kt:38)
	at kotlinx.coroutines.BuildersKt.runBlocking$default(Unknown Source)
	at standardcoroutine.ExceptionHandlingKt.main(ExceptionHandling.kt:6)
	at standardcoroutine.ExceptionHandlingKt.main(ExceptionHandling.kt)
```

launch는 코루틴을 생성하는 데 사용되는 함수일 뿐으로 람다식의 실행은 생성된 코루틴이 CoroutineDispatcher에 의해 스레드로 분배되는 시점에 일어나기 때문이다.
즉, 이 try catch문은 launch 코루틴 빌더 함수 자체의 실행만 체크하며, 람다식은 예외 처리 대상이 아니다. 

## async의 예외 처리

async 코루틴 빌더 함수는 다른 코루틴 빌더 함수와 달리 결과값을 Deferred 객체로 감싸고 await 호출 시점에 결과값을 노출한다.
이런 특성 때문에 코루틴 실행 도중 예외가 발생해 결과값이 없다면 Deferred에 대한 await 호출 시 예외가 노출된다.

```kotlin
suspend fun asyncExceptionHandlingTest() {
    supervisorScope {
        val deferred = async(CoroutineName("Coroutine1")) {
            throw Exception("Coroutine1 예외 발생!!")
        }
        try {
            deferred.await()
        } catch (e: Exception) {
            println("[노출된 예외] ${e.message}")
        }
    }
}
```

### async 예외 전파

async 코루틴 빌더 함수 사용 시 많이 하는 실수 중 하나는 await 함수 호출부에서만 예외 처리를 하는 것이다.
async 코루틴 빌더 함수도 예외가 발생하면 부모 코루틴으로 예외를 전파하는데 이를 적절하게 처리해야 한다.

```kotlin
suspend fun mistakeAsyncExceptionHandlingTest(coroutineScope: CoroutineScope) {
    val deferred = coroutineScope.async(CoroutineName("Coroutine1")) {
        throw Exception("Coroutine1 예외 발생!!")
    }
    try {
        deferred.await()
    } catch (e: Exception) {
        println("[노출된 예외] ${e.message}")
    }
    coroutineScope.launch(CoroutineName("Coroutine2")) {
        delay(100)
        println("[${Thread.currentThread().name}] 코루틴 실행 완료")
    }
}
```

```text
[노출된 예외] Coroutine1 예외 발생!!
Exception in thread "main" java.lang.Exception: Coroutine1 예외 발생!!
	at standardcoroutine.ExceptionHandlingKt$mistakeAsyncExceptionHandlingTest$deferred$1.invokeSuspend(ExceptionHandling.kt:27)
	at kotlin.coroutines.jvm.internal.BaseContinuationImpl.resumeWith(ContinuationImpl.kt:33)
	at kotlinx.coroutines.DispatchedTask.run(DispatchedTask.kt:108)
	at kotlinx.coroutines.EventLoopImplBase.processNextEvent(EventLoop.common.kt:280)
	at kotlinx.coroutines.BlockingCoroutine.joinBlocking(Builders.kt:85)
	at kotlinx.coroutines.BuildersKt__BuildersKt.runBlocking(Builders.kt:59)
	at kotlinx.coroutines.BuildersKt.runBlocking(Unknown Source)
	at kotlinx.coroutines.BuildersKt__BuildersKt.runBlocking$default(Builders.kt:38)
	at kotlinx.coroutines.BuildersKt.runBlocking$default(Unknown Source)
	at standardcoroutine.ExceptionHandlingKt.main(ExceptionHandling.kt:5)
	at standardcoroutine.ExceptionHandlingKt.main(ExceptionHandling.kt)
```

코루틴1의 예외가 부모 코루틴인 runBlocking 코루틴에 전파되어 코루틴2도 취소된다.
이를 해결하기 위해서는 코루틴1에서 발생한 예외가 부모 코루틴으로 전파되지 않도록 만들어야 한다. supervisorScope를 사용해 예외 전파를 제한시킬 수 있다.

```kotlin
suspend fun blockingAsyncExceptionPropagationUsingSupervisorScopeTest() {
    supervisorScope {
        async(CoroutineName("Coroutine1")) {
            throw Exception("Coroutine1 예외 발생!!")
        }
        launch(CoroutineName("Coroutine2")) {
            delay(100)
            println("[${Thread.currentThread().name}] 코루틴 실행 완료")
        }
    }
}
```

```
[main @Coroutine2#3] 코루틴 실행 완료
```

## 전파되지 않는 예외

코루틴은 CancellationException 예외가 발생해도 부모 코루틴으로 전파되지 않는다.

```kotlin
suspend fun cancellationExceptionTest(coroutineScope: CoroutineScope) {
    coroutineScope.launch(CoroutineName("Coroutine1")) {
        launch(CoroutineName("Coroutine2")) {
            throw CancellationException()
        }
        delay(100)
        println("[${Thread.currentThread().name}] 코루틴 실행")
    }
    delay(100)
    println("[${Thread.currentThread().name}] 코루틴 실행")
}
```

```text
[main @coroutine#1] 코루틴 실행
[main @Coroutine1#2] 코루틴 실행
```

일반적인 예외가 발생했다면 루트 코루틴까지 전파되어 프로세스가 종료되어야 하지만 CancellationException은 코루틴2만 취소시키고 전파되지 않는다.

**왜 CancellationException을 부모 코루틴으로 전파하지 않는것일까?** 

### 코루틴 취소 시 사용되는 JobCancellationException 

CancellationException은 코루틴의 취소에 사용되는 특별한 예외이기 때문에 부모 코루틴으로 전파하지 않는다.
Job 객체에 대한 cancel 함수를 호출하면 CancellationException의 서브 클래스인 JobCancellationException을 발생시켜 코루틴을 취소시킨다.

```kotlin
fun cancellationExceptionTest2(coroutineScope: CoroutineScope) {
    val job = coroutineScope.launch {
        delay(1000L)
    }
    job.invokeOnCompletion { exception ->
        println(exception)
    }
    job.cancel()
}
```

```text
kotlinx.coroutines.JobCancellationException: StandaloneCoroutine was cancelled; job="coroutine#2":StandaloneCoroutine{Cancelled}@51b279c9
```

코드 실행 결과를 보면 JobCancellationException이 발생해 코루틴이 취소되는 것을 확인할 수 있다.

### withTimeOut 사용해 코루틴의 실행 시간 제한하기

```kotlin
public suspend fun <T> withTimeout(timeMillis: Long, block: suspend CoroutineScope.() -> T): T
```

withTimeOut 함수는 매개변수로 실행 제한 시간을 밀리초 단위로 표현하는 timeMillis와 해당 시간 내에 실행돼야 할 작업인 block을 가진다.
withTimeOut 함수는 주어진 시간 내에 완료되지 않으면 TimeoutCancellationException을 발생시키는데 이는 CancellationException의 서브 클래스이다.
따라서 TimeoutCancellationException이 발생되더라도 예외가 부모 코루틴으로 전파되지 않고 해당 예외가 발생한 코루틴만 취소된다.

```kotlin
suspend fun withTimeOutTest(coroutineScope: CoroutineScope) {
    coroutineScope.launch(CoroutineName("Coroutine1")) {
        withTimeout(1000L) {
            delay(2000L)
            println("[${Thread.currentThread().name}] 코루틴 실행")
        }
    }
    delay(2000)
    println("[${Thread.currentThread().name}] 코루틴 실행")
}
```

```text
[main @coroutine#1] 코루틴 실행
```

### withTimeOutOrNull

실행 시간 초과 시 해당 코루틴을 취소시키는 것이 아닌 결과가 반환돼야 하는 경우가 있다.
이런 경우를 위해 withTimeOutOrNull 함수를 사용해볼 수 있다.
withTimeOutOrNull는 코루틴이 취소되지 않고 null을 반환한다.

```kotlin
suspend fun withTimeoutOrNullTest(coroutineScope: CoroutineScope) {
    coroutineScope.launch(CoroutineName("Coroutine1")) {
        val result = withTimeoutOrNull(1000L) {
            delay(2000L)
            return@withTimeoutOrNull "결과"
        }
        println(result)
    }
}
```

```kotlin
null
```