# 5강. 코루틴의 예외 처리와 Job의 상태 변화

## 루트 코루틴을 만드는 방법

```kotlin
fun main(): Unit = runBlocking {
    val job1 = launch {
        delay(1000)
        printWithThread("Job 1")
    }

    val job2 = launch {
        delay(1000)
        printWithThread("Job 2")
    }
}
```

위와 같은 구조를 트리로 구성하면 아래와 같다.

<img width="582" alt="image" src="https://github.com/yoon-youngjin/spring-study/assets/83503188/08bd11b1-8d0b-4231-a1f5-57bb0886cbea">

이러한 구조에서 runBlocking으로 생성된 코루틴을 루트 코루틴이라고 한다.

**새로운 루트 코루틴을 만들고 싶다면?**

새로운 영역(CoroutineScope)을 만들어야 한다!

```kotlin
fun main(): Unit = runBlocking {
    val job1 = CoroutineScope(Dispatchers.Default).launch {
        delay(1000)
        printWithThread("Job 1")
    }

    val job2 = CoroutineScope(Dispatchers.Default).launch {
        delay(1000)
        printWithThread("Job 2")
    }
}
```
- CoroutineScope을 통해 새로운 영역을 만들고, Dispatchers.Default을 통해 메인 스레드가 아닌 별도의 스레드에서 실행하도록 구성할 수 있다.

<img width="619" alt="image" src="https://github.com/yoon-youngjin/spring-study/assets/83503188/de20f71c-192e-454d-ab82-f832428c86aa">

## launch, async 예외 발생 차이

### launch

```kotlin
fun main(): Unit = runBlocking {
    val job = CoroutineScope(Dispatchers.Default).launch {
        throw IllegalArgumentException()
    }

    delay(1000)
}
```

<img width="610" alt="image" src="https://github.com/yoon-youngjin/spring-study/assets/83503188/d59045eb-8d0e-480c-9365-6d815a847dd6">

launch의 경우 오류가 발생하면 오류를 출력하고 바로 종료된다.

### aysnc

```kotlin
fun main(): Unit = runBlocking {
    val job = CoroutineScope(Dispatchers.Default).async {
        throw IllegalArgumentException()
    }

    delay(1000)
}
```

<img width="496" alt="image" src="https://github.com/yoon-youngjin/spring-study/assets/83503188/b7ff9ee9-9b17-4cc9-816e-91d901e0ace6">

async는 예외가 출력되지 않고 종료된다. async에서 예외를 보기 위해선 await을 통해 결과를 받아와야한다.

```kotlin
fun main(): Unit = runBlocking {
    val job = async {
        throw IllegalArgumentException()
    }
    delay(1000)
}
```

위의 코드는 이전 코드와 달리 새로운 영역을 만들지 않고 runBlocking의 자식 코루틴으로 수행한다.

<img width="734" alt="image" src="https://github.com/yoon-youngjin/spring-study/assets/83503188/3698c893-37d9-4a3e-ab6a-94e2db10adce">

이러한 경우 앞의 경우와 달리 오류를 출력하고 종료된다.

이것에 대한 이유는 자식 코루틴의 예외는 부모에게 전파되기 때문이다.

<img width="524" alt="image" src="https://github.com/yoon-youngjin/spring-study/assets/83503188/5e19d2ab-485a-4c28-a962-9b305c0823cb">

launch, await에 상관없이 자식 코루틴은 부모 코루틴으로 예외를 전달한다. runBlocking도 예외를 출력하는 성질을 가지고 있다.
즉, 이전에는 본인이 루트 코루틴이었기 때문에 전파 대상이 없어 예외를 출력하지 않은 것이다.

### 만약 자식 코루틴의 예외를 부모에게 전파하고 싶지 않다면?

루트 코루틴 외에 SupervisorJob()을 활용해볼 수 있다.

```kotlin
fun main(): Unit = runBlocking {
    val job = async(SupervisorJob()) {
        throw IllegalArgumentException()
    }

    delay(1000)
}
```
- 부모, 자식 관계는 유지되지만 자식의 예외를 전파하지 않을 수 있다.
- 물론 job.await()을 통해 예외를 출력해볼 수 있다.

## 예외를 다루는 방법

### 직관적인 try-catch-finally

```kotlin
fun main(): Unit = runBlocking {
    val job = launch {
        try {
            throw IllegalArgumentException()
        } catch (e: IllegalArgumentException) {
            printWithThread("정상 종료")
        }
    }
}
```

### CoroutineExceptionHandler

진짜 에러는 발생한 것으로 간주되었는데, 에러를 로깅, 에러 메시지를 전달하는 등의 공통된 로직을 처리하고 싶다면 CoroutineExceptionHandler를 활용해볼 수 있다.

**CoroutineExceptionHandler의 두 가지 파라미터**

```kotlin
val exceptionHandler = CoroutineExceptionHandler { context, throwable -> 
    ...
}
```
- context : 코루틴 구성요소
- throwable : 발생한 예외

```kotlin
fun main(): Unit = runBlocking {
    val exceptionHandler = CoroutineExceptionHandler { _, _ ->
        printWithThread("예외")
    }
    val job = CoroutineScope(Dispatchers.Default).launch(exceptionHandler) {
        throw IllegalArgumentException()
    }

    delay(1000)
}
```

<img width="551" alt="image" src="https://github.com/yoon-youngjin/spring-study/assets/83503188/6f0227ca-522e-49bc-b4fa-66a810cce17e">

실제 에러를 던지고 싶다면 exceptionHandler의 파라미터인 throwable을 throw하면 된다. -> `throw throwable`

**CoroutineExceptionHandler 주의할 점**

1. launch에만 적용이 가능하다.
2. 부모 코루틴이 있으면 동작하지 않는다.

### 코루틴 취소 예외 한 방 정리

- case1 : 발생한 예외가 CancellationException인 경우 **취소**로 간주하고 부모 코루틴에게 전파 X
- case2 : 그 외 다른 예외가 발생한 경우 **실패**로 간주하고 부모 코루틴으로 전파

하지만, 내부적으로 취소나 실패 모두 `취소됨` 상태로 관리한다.

**Job(코루틴)의 Life Cycle**

<img width="624" alt="image" src="https://github.com/yoon-youngjin/spring-study/assets/83503188/c327b3b6-6969-4794-87f2-42a71e56566d">

- Lazy로 생성한 경우 NEW에 멈춰있다가 start()시에 ACTIVE 상태가 되고, 일반적으로 생성한 경우에는 바로 ACTIVE 상태가 된다.
- 예외(CancellationException, 그 외)가 발생하면 CANCELLING 상태가 되고, 최종적으로 CANCELLED 상태가 된다.
- CancellationException인지 그 외 예외인지가 중요한 이유는 내부적으로는 CANCELLED 상태로 보이지만 그 예외를 부모 코루틴에게 전파하냐 안하냐의 차이가 존재한다.
- ACTIVE 상태에서 작업이 성공되었다면 COMPLETING 상태가 되었다가 COMPLETED 상태로 변경된다.

**COMPLETING, COMPLETED를 나눠지는 이유는?** 